{
  "dataType": "CVE_RECORD",
  "containers": {
    "adp": [
      {
        "title": "CISA ADP Vulnrichment",
        "metrics": [
          {
            "other": {
              "type": "ssvc",
              "content": {
                "id": "CVE-2024-3219",
                "role": "CISA Coordinator",
                "options": [
                  {
                    "Exploitation": "none"
                  },
                  {
                    "Automatable": "no"
                  },
                  {
                    "Technical Impact": "partial"
                  }
                ],
                "version": "2.0.3",
                "timestamp": "2024-07-31T18:45:03.016211Z"
              }
            }
          }
        ],
        "providerMetadata": {
          "orgId": "134c704f-9b21-4f2e-91b3-4a467353bcc0",
          "shortName": "CISA-ADP",
          "dateUpdated": "2024-07-31T18:45:08.194Z"
        }
      }
    ],
    "cna": {
      "title": "Pure-Python fallback of socket.socketpair() doesn\u2019t authenticate peer connection",
      "source": {
        "discovery": "UNKNOWN"
      },
      "credits": [
        {
          "lang": "en",
          "type": "reporter",
          "value": "Ellie"
        }
      ],
      "affected": [
        {
          "vendor": "Python Software Foundation",
          "product": "CPython",
          "versions": [
            {
              "status": "affected",
              "version": "0",
              "versionType": "python",
              "lessThanOrEqual": "3.13.0b4"
            }
          ],
          "platforms": [
            "Windows"
          ],
          "defaultStatus": "unaffected"
        }
      ],
      "references": [
        {
          "url": "https://github.com/python/cpython/pull/122134",
          "tags": [
            "patch"
          ]
        },
        {
          "url": "https://github.com/python/cpython/issues/122133",
          "tags": [
            "issue-tracking"
          ]
        },
        {
          "url": "https://mail.python.org/archives/list/security-announce@python.org/thread/WYKDQWIERRE2ICIYMSVRZJO33GSCWU2B/",
          "tags": [
            "vendor-advisory"
          ]
        },
        {
          "url": "http://www.openwall.com/lists/oss-security/2024/07/29/3"
        },
        {
          "url": "https://github.com/python/cpython/commit/06fa244666ec6335a3b9bf2367e31b42b9a89b20",
          "tags": [
            "patch"
          ]
        },
        {
          "url": "https://github.com/python/cpython/commit/0b65c8bf5367625673eafb92f85046a1b31259f2",
          "tags": [
            "patch"
          ]
        },
        {
          "url": "https://github.com/python/cpython/commit/220e31adeaaa8436c9ff234cba1398bc49e2bb6c",
          "tags": [
            "patch"
          ]
        },
        {
          "url": "https://github.com/python/cpython/commit/5f90abaa786f994db3907fc31e2ee00ea2cf0929",
          "tags": [
            "patch"
          ]
        },
        {
          "url": "https://github.com/python/cpython/commit/b252317956b7fc035bb3774ef6a177e227f9fc54",
          "tags": [
            "patch"
          ]
        }
      ],
      "x_generator": {
        "engine": "Vulnogram 0.2.0"
      },
      "descriptions": [
        {
          "lang": "en",
          "value": "There is a MEDIUM severity vulnerability affecting CPython.\n\nThe\n \u201csocket\u201d module provides a pure-Python fallback to the \nsocket.socketpair() function for platforms that don\u2019t support AF_UNIX, \nsuch as Windows. This pure-Python implementation uses AF_INET or \nAF_INET6 to create a local connected pair of sockets. The connection \nbetween the two sockets was not verified before passing the two sockets \nback to the user, which leaves the server socket vulnerable to a \nconnection race from a malicious local peer.\n\nPlatforms that support AF_UNIX such as Linux and macOS are not affected by this vulnerability. Versions prior to CPython 3.5 are not affected due to the vulnerable API not being included.",
          "supportingMedia": [
            {
              "type": "text/html",
              "value": "There is a MEDIUM severity vulnerability affecting CPython.<br><br>The\n \u201csocket\u201d module provides a pure-Python fallback to the \nsocket.socketpair() function for platforms that don\u2019t support AF_UNIX, \nsuch as Windows. This pure-Python implementation uses AF_INET or \nAF_INET6 to create a local connected pair of sockets. The connection \nbetween the two sockets was not verified before passing the two sockets \nback to the user, which leaves the server socket vulnerable to a \nconnection race from a malicious local peer.<br><br>Platforms that support AF_UNIX such as Linux and macOS are not affected by this vulnerability. Versions prior to CPython 3.5 are not affected due to the vulnerable API not being included.<br>",
              "base64": false
            }
          ]
        }
      ],
      "providerMetadata": {
        "orgId": "28c92f92-d60d-412d-b760-e73465c3df22",
        "shortName": "PSF",
        "dateUpdated": "2024-07-30T12:45:56.043Z"
      }
    }
  },
  "cveMetadata": {
    "cveId": "CVE-2024-3219",
    "state": "PUBLISHED",
    "dateUpdated": "2024-07-31T18:45:11.922Z",
    "dateReserved": "2024-04-02T18:03:22.557Z",
    "assignerOrgId": "28c92f92-d60d-412d-b760-e73465c3df22",
    "datePublished": "2024-07-29T21:54:05.830Z",
    "assignerShortName": "PSF"
  },
  "dataVersion": "5.1"
}